vagrant_kafka_1
Error response from daemon: No such container: vagrant_zookeper_1
cassandra
Error: failed to start containers: vagrant_zookeper_1
Data stream open. Records sent:
{'id': 63956, 'name': 'Tsirmpas Dimitris', 'song': 'Kolor', 'time': '2024-02-29 01:54'}
^CTraceback (most recent call last):
  File "src/data-producer.py", line 76, in <module>
    result = loop.run_until_complete(produce())
  File "/usr/lib/python3.6/asyncio/base_events.py", line 471, in run_until_complete
    self.run_forever()
  File "/usr/lib/python3.6/asyncio/base_events.py", line 438, in run_forever
    self._run_once()
  File "/usr/lib/python3.6/asyncio/base_events.py", line 1451, in _run_once
    handle._run()
  File "/usr/lib/python3.6/asyncio/events.py", line 145, in _run
    self._callback(*self._args)
  File "src/data-producer.py", line 70, in produce
    time.sleep(INTERVAL_SECS)
KeyboardInterrupt
